<?xml version='1.0' encoding='utf-8'?>
<robot name="partnet_10798ccb7072393e86d53ab0fe94e911">
  <link name="base" />
  <link name="link_0">
    <visual name="part_01">
      <origin xyz="-0.18202803 0.00000000 -0.20976162" />
      <geometry>
        <mesh filename="part_01.glb" />
      </geometry>
    </visual>
    <collision>
      <origin xyz="-0.18202803 0.00000000 -0.20976162" />
      <geometry>
        <mesh filename="part_01.glb" />
      </geometry>
    </collision>
  </link>
  <joint name="joint_0" type="revolute">
    <origin xyz="0.18202803 0.00000000 0.20976162" />
    <axis xyz="0 -1 0" />
    <child link="link_0" />
    <parent link="link_1" />
    <limit lower="-0.0" upper="2.8274333882308134" />
  </joint>
  <link name="link_1">
    <visual name="part_00">
      <origin xyz="0 0 0" />
      <geometry>
        <mesh filename="part_00.glb" />
      </geometry>
    </visual>
    <collision>
      <origin xyz="0 0 0" />
      <geometry>
        <mesh filename="part_00.glb" />
      </geometry>
    </collision>
  </link>
  <joint name="joint_1" type="fixed">
    <origin rpy="1.570796326794897 0 -1.570796326794897" xyz="0 0 0" />
    <child link="link_1" />
    <parent link="base" />
  </joint>
</robot>